Workbook
Name Choose_Single__Double_or_No: 'Data Tables'!$J$10:$J$14
Name Choose_Yes_or_No: 'Data Tables'!$J$5:$J$8
Name Door_Model: 'Data Tables'!$A$2:$A$6
Name Track_Size: 'Data Tables'!$J$1:$J$3
Name Windows: 'Data Tables'!$Z$1:$Z$7

Sheet New Input Data
A2: TX450-20 | D2: 7 | E2: 8 | F2: '' x | G2: 7 | H2: 11 | I2: (WxH)

Sheet Work Order
A1: TX450 | E1: 16 | F1: 2 | G1: x | H1: 14 | I1: 2 | J1: (W x H)
B2: Panels & | F2: Sections
A3: R112G - 34" x 16" Thermo. Window | I3: Low Head Room Front Mount | O3: 3 | P3: Track
A4: UST =
A5: 1.25 | C5: Solid Shaft
A6: Angle Mount | E6: on | F6: Steel
A7: 1 | B7: pcs x | D7: 1.25 | F7: Shaft Coupling | I7: , | J7: Pillow Bearing
A8: Weatherstrip (Alum. Stops, mill finish, c/w vinyl)
A9: Hat Strut 20 Ga | E9: pcs
A10: Double end hinges | E10: & | F10: =O3 -> 3 | G10: Rollers | I10: Double end Frame
A11: Double end caps | E11: 20 | F11: Gauge
A12: Wrapping
A13: Serial #:
A16: Hinge Location: | D16: 1) | E16: 48 | F16: 2) | G16: 97 | H16: 3) | I16: 145

Sheet Sprinc Calc
B1: Coil | C1: Wire | D1: Length | E1: Qty | F1: Galv | G1: Cycles | H1: Cycles Calc
A2: Spring: | B2: ='Input Data'!E43 -> 2.625 | C2: =SUMIFS(B39:B58,A39:A58,B2,D39:D58,G2,H39:H58,1) -> 0 | D2: =SUMIFS(I39:I58,A39:A58,B2,D39:D58,G2) -> 0 | E2: ='Input Data'!D43 -> 4 | F2: ='Input Data'!H43 -> No | G2: ='Input Data'!I43 -> 10000 | H2: =IF(G2=100000,ROUND(O37/1000,0)*1000,ROUND(O33/1000,0)*1000) -> #N/A
F3: Cycle Column | G3: =IF(G2=10000,2,IF(G2=15000,3,IF(G2=25000,4,IF(G2=50000,5,IF(G2=100000,6,0))))) -> 2
B4: Maximum Inch Pound (MIP) Spring Capacity Table | I4: Divider and Dead Coil Factor Table | S4: Divider and Dead Coil Factor Table
I5: Oil Spring | S5: Galvanized Spring
C6: Cycles | J6: Coil Diameter | N6: Dead Coil Factor (1) | T6: Coil Diameter | X6: Dead Coil Factor (1)
B7: Wire Diam | C7: 10000 (2) | D7: 15000 (3) | E7: 25000(4) | F7: 50000(5) | G7: 100000(6) | I7: Wire Diam | J7: 2 | K7: 2.625 | L7: 3.75 | M7: 6 | N7: Factor 1 | O7: Factor 2 | S7: Wire Diam | T7: 2 | U7: 2.625 | V7: 3.75 | W7: 6 | X7: Factor 1 | Y7: Factor 2
A8: 1 | B8: 0.218 | C8: 247 | D8: 229 | E8: 206 | F8: 177 | G8: 153 | I8: 0.218 | J8: 664.5 | N8: 1.09 | O8: 0.66 | S8: 0.218 | T8: 664.5 | X8: 1.09 | Y8: 0.66
A9: 2 | B9: 0.225 | C9: 268 | D9: 249 | E9: 224 | F9: 193 | G9: 166 | I9: 0.225 | J9: 768.8 | N9: 1.13 | O9: 0.68 | S9: 0.225 | T9: 768.8 | X9: 1.13 | Y9: 0.68
A10: 3 | B10: 0.234 | C10: 298 | D10: 276 | E10: 249 | F10: 214 | G10: 184 | I10: 0.234 | J10: 933.3 | N10: 1.17 | O10: 0.7 | S10: 0.234 | T10: 933.3 | X10: 1.17 | Y10: 0.7
A11: 4 | B11: 0.243 | C11: 337 | D11: 309 | E11: 279 | F11: 240 | G11: 206 | I11: 0.243 | J11: 1129 | N11: 1.22 | O11: 0.73 | S11: 0.243 | T11: 1129 | X11: 1.22 | Y11: 0.73
A12: 5 | B12: 0.25 | C12: 358 | D12: 332 | E12: 300 | F12: 257 | G12: 222 | I12: 0.25 | J12: 1279.1 | K12: 1001 | L12: 719.5 | N12: 1.25 | O12: 0.75 | S12: 0.25 | T12: 1279.1 | U12: 1001 | V12: 0 | X12: 1.25 | Y12: 0.75
A13: 6 | B13: 0.262 | C13: 411 | D13: 381 | E13: 343 | F13: 295 | G13: 254 | I13: 0.262 | J13: 1623.4 | K13: 1272 | L13: 915.4 | N13: 1.31 | O13: 0.79 | S13: 0.262 | T13: 1623.4 | U13: 1272 | V13: 915.4 | X13: 1.31 | Y13: 0.79
A14: 7 | B14: 0.273 | C14: 458 | D14: 425 | E14: 383 | F14: 329 | G14: 283 | I14: 0.273 | J14: 1966 | K14: 1542 | L14: 1110.8 | N14: 1.37 | O14: 0.82 | S14: 0.273 | T14: 1966 | U14: 1542 | V14: 1110.8 | X14: 1.37 | Y14: 0.82
A15: 8 | B15: 0.283 | C15: 506 | D15: 470 | E15: 424 | F15: 364 | G15: =313 -> 313 | I15: 0.283 | J15: 2343.1 | K15: 1839.5 | L15: 1326.4 | N15: 1.42 | O15: 0.85 | S15: 0.283 | T15: 2343.1 | U15: 1839.5 | V15: 1326.4 | X15: 1.42 | Y15: 0.85
A16: 9 | B16: 0.295 | C16: 569 | D16: 527 | E16: 476 | F16: 408 | G16: 352 | I16: 0.295 | K16: 2254.8 | L16: 1627.7 | N16: 1.48 | O16: 0.89 | S16: 0.295 | U16: 2254.8 | V16: 1627.7 | X16: 1.48 | Y16: 0.89
A17: 10 | B17: 0.306 | C17: 633 | D17: 587 | E17: 529 | F17: 454 | G17: 391 | I17: 0.306 | L17: 1965.1 | N17: 1.52 | O17: 0.92 | S17: 0.306 | U17: 0 | V17: 1965.1 | X17: 1.52 | Y17: 0.92
A18: 11 | B18: 0.312 | C18: 668 | D18: 619 | E18: 559 | F18: 480 | G18: 413 | I18: 0.312 | K18: 2989.8 | L18: 2161.9 | M18: =1391.3*0 -> 0 | N18: 1.56 | O18: 0.94 | S18: 0.312 | U18: 2989.8 | V18: 2161.9 | W18: 0 | X18: 1.56 | Y18: 0.94
A19: 12 | B19: 0.319 | C19: 710 | D19: 659 | E19: 594 | F19: 510 | G19: 439 | I19: 0.319 | L19: 2410.9 | M19: 1552.5 | N19: 1.6 | O19: 0.96 | S19: 0.319 | V19: 2410.9 | W19: 0 | X19: 1.6 | Y19: 0.96
A20: 13 | B20: 0.331 | C20: 784 | D20: 727 | E20: 656 | F20: 563 | G20: 485 | I20: 0.331 | L20: 2869.1 | M20: 1849.4 | N20: 1.66 | O20: 0.99 | S20: 0.331 | V20: 0 | W20: 0 | X20: 1.66 | Y20: 0.99
A21: 14 | B21: 0.343 | C21: 871 | D21: 808 | E21: 729 | F21: 626 | G21: 538 | I21: 0.343 | L21: 3452.7 | M21: 2228.1 | N21: 1.72 | O21: 1.03 | S21: 0.343 | V21: 0 | W21: 2228.1 | X21: 1.72 | Y21: 1.03
A22: 15 | B22: 0.362 | C22: 1011 | D22: 937 | E22: 845 | F22: 726 | G22: 625 | I22: 0.362 | L22: 4485.5 | M22: 2899.3 | N22: 1.81 | O22: 1.09 | S22: 0.362 | V22: 0 | W22: 2899.3 | X22: 1.81 | Y22: 1.09
A23: 16 | B23: 0.375 | C23: 1111 | D23: 1030 | E23: 929 | F23: 798 | G23: 687 | I23: 0.375 | M23: 3428.1 | N23: 1.88 | O23: 1.13 | S23: 0.375 | W23: 3428.1 | X23: 1.88 | Y23: 1.13
A24: 17 | B24: 0.393 | C24: 1273 | D24: 1181 | E24: 1065 | F24: 914 | G24: 787 | I24: 0.393 | M24: 4365.1 | N24: 1.97 | O24: 1.18 | S24: 0.393 | W24: 0 | X24: 1.97 | Y24: 1.18
A25: 18 | B25: 0.406 | C25: 1388 | D25: 1287 | E25: 1161 | F25: 997 | G25: 858 | I25: 0.406 | M25: 5087.1 | N25: 2.03 | O25: 1.22 | S25: 0.406 | W25: 0 | X25: 2.03 | Y25: 1.22
A26: 19 | B26: 0.437 | C26: 1708 | D26: 1584 | E26: 1428 | F26: 1227 | G26: 1056 | I26: 0.437 | M26: 7337.1 | N26: 2.19 | O26: 1.31 | S26: 0.437 | W26: 0 | X26: 2.19 | Y26: 1.31
B28: Wire | C28: =IF(C8>=$F$35,$B$8,IF(C9>=$F$35,$B$9,IF(C10>=$F$35,$B$10,IF(C11>=$F$35,$B$11,IF(C12>=$F$35,$B$12,IF(C13>=$F$35,$B$13,IF(C14>=$F$35,$B$14,IF(C15>=$F$35,$B$15,IF(C16>=$F$35,$B$16,IF(C17>=$F$35,$B$17,IF(C18>=$F$35,$B$18,(IF(C19>=$F$35,$B$19,IF(C20>=$F$35,$B$20,IF(C21>=$F$35,$B$21,IF(C22>=$F$35,$B$22,IF(C23>=$F$35,$B$23,IF(C24>=$F$35,$B$24,IF(C25>=$F$35,$B$25,IF(C26>=$F$35,$B$26,0)))))))))))))))))))) -> 0.312 | D28: =IF(D8>=$F$35,$B$8,IF(D9>=$F$35,$B$9,IF(D10>=$F$35,$B$10,IF(D11>=$F$35,$B$11,IF(D12>=$F$35,$B$12,IF(D13>=$F$35,$B$13,IF(D14>=$F$35,$B$14,IF(D15>=$F$35,$B$15,IF(D16>=$F$35,$B$16,IF(D17>=$F$35,$B$17,IF(D18>=$F$35,$B$18,(IF(D19>=$F$35,$B$19,IF(D20>=$F$35,$B$20,IF(D21>=$F$35,$B$21,IF(D22>=$F$35,$B$22,IF(D23>=$F$35,$B$23,IF(D24>=$F$35,$B$24,IF(D25>=$F$35,$B$25,IF(D26>=$F$35,$B$26,0)))))))))))))))))))) -> 0.331 | E28: =IF(E8>=$F$35,$B$8,IF(E9>=$F$35,$B$9,IF(E10>=$F$35,$B$10,IF(E11>=$F$35,$B$11,IF(E12>=$F$35,$B$12,IF(E13>=$F$35,$B$13,IF(E14>=$F$35,$B$14,IF(E15>=$F$35,$B$15,IF(E16>=$F$35,$B$16,IF(E17>=$F$35,$B$17,IF(E18>=$F$35,$B$18,(IF(E19>=$F$35,$B$19,IF(E20>=$F$35,$B$20,IF(E21>=$F$35,$B$21,IF(E22>=$F$35,$B$22,IF(E23>=$F$35,$B$23,IF(E24>=$F$35,$B$24,IF(E25>=$F$35,$B$25,IF(E26>=$F$35,$B$26,0)))))))))))))))))))) -> 0.343 | F28: =IF(F8>=$F$35,$B$8,IF(F9>=$F$35,$B$9,IF(F10>=$F$35,$B$10,IF(F11>=$F$35,$B$11,IF(F12>=$F$35,$B$12,IF(F13>=$F$35,$B$13,IF(F14>=$F$35,$B$14,IF(F15>=$F$35,$B$15,IF(F16>=$F$35,$B$16,IF(F17>=$F$35,$B$17,IF(F18>=$F$35,$B$18,(IF(F19>=$F$35,$B$19,IF(F20>=$F$35,$B$20,IF(F21>=$F$35,$B$21,IF(F22>=$F$35,$B$22,IF(F23>=$F$35,$B$23,IF(F24>=$F$35,$B$24,IF(F25>=$F$35,$B$25,IF(F26>=$F$35,$B$26,0)))))))))))))))))))) -> 0.362 | G28: =IF(G8>=$F$35,$B$8,IF(G9>=$F$35,$B$9,IF(G10>=$F$35,$B$10,IF(G11>=$F$35,$B$11,IF(G12>=$F$35,$B$12,IF(G13>=$F$35,$B$13,IF(G14>=$F$35,$B$14,IF(G15>=$F$35,$B$15,IF(G16>=$F$35,$B$16,IF(G17>=$F$35,$B$17,IF(G18>=$F$35,$B$18,(IF(G19>=$F$35,$B$19,IF(G20>=$F$35,$B$20,IF(G21>=$F$35,$B$21,IF(G22>=$F$35,$B$22,IF(G23>=$F$35,$B$23,IF(G24>=$F$35,$B$24,IF(G25>=$F$35,$B$25,IF(G26>=$F$35,$B$26,0)))))))))))))))))))) -> 0.375 | I28: Note 1: | J28: If coil Diameter is smaller than 3.5 choose Factor 1, otherwise choose Factor 2. | S28: Note 1: | T28: If coil Diameter is smaller than 3.5 choose Factor 1, otherwise choose Factor 2.
E30: Drum Width | F30: ='Sub Routine Drums'!S21 -> 3.33 | K30: interpolation
E31: Space between springs (min) | F31: 6 | K31: X1 | L31: =VLOOKUP(C2,B8:G26,G3,FALSE) -> #N/A | N31: X2 | O31: =VLOOKUP(C2,B8:G26,G3+1,FALSE) -> #N/A
E32: Free space (min) | F32: 6 | K32: Y1 | L32: =G2 -> 10000 | N32: Y2 | O32: =IF(L32=10000,15000,IF(L32=15000,25000,IF(L32=25000,50000,IF(L32=50000,100000,0)))) -> 15000
E33: Turns | F33: ='Input Data'!E41 -> 10.7 | K33: X | L33: =F35 -> 663.06562 | N33: Y2 | O33: =(L33-L31)*(O32-L32)/(O31-L31)+L32 -> #N/A
E34: IPPT | F34: ='Input Data'!I41 -> 247.875
E35: MIP | F35: =F34*F33/F36 -> 663.06562 | K35: X1 | L35: =VLOOKUP(C2,B8:G26,G3-1,FALSE) -> #N/A | N35: X2 | O35: =VLOOKUP(C2,B8:G26,6,FALSE) -> #N/A
E36: Spring Qty | F36: ='Input Data'!D43 -> 4 | K36: Y1 | L36: =50000 -> 50000 | N36: Y2 | O36: 100000
A37: Single Spring | K37: X | L37: =F35 -> 663.06562 | N37: Y2 | O37: =(L37-L35)*(O36-L36)/(O35-L35)+L36 -> #N/A
A38: Coil Diam | B38: Wire | C38: Total Spring Length | D38: Cycles | E38: Divider | F38: Dead Coil Factor 1,2 | G38: Spring Assembly Length | H38: Spring Length Conditions | I38: Spring Lengh Filtered
A39: 2 | B39: =$C$28 -> 0.312 | C39: =IF(E39=0,0,$F$36*E39/$F$34+F39) -> 0 | D39: 10000 | E39: =IF('Input Data'!$H$43="No",SUMIFS($J$8:$J$26,$I$8:$I$26,B39),SUMIFS($T$8:$T$26,$S$8:$S$26,B39)) -> 0 | F39: =SUMIFS($X$8:$X$26,$S$8:$S$26,B39) -> 1.56 | G39: =IF(C39=0,0,(B39*$F$33+3+C39)*$F$36+($F$36-1)*$F$31+(2+'Input Data'!$E$18)*$F$30) -> 0 | H39: =IF(AND($E$60<=C39,C39<$E$59),IF(G39=0,0,IF(G39<'Input Data'!$F$4*IF('Input Data'!$J$43="Yes",2,1)-$F$32,1,0)),0) -> 0 | I39: =C39*H39 -> 0
A40: =A39 -> 2 | B40: =$D$28 -> 0.331 | C40: =IF(E40=0,0,$F$36*E40/$F$34+F40) -> 0 | D40: 15000 | E40: =IF('Input Data'!$H$43="No",SUMIFS($J$8:$J$26,$I$8:$I$26,B40),SUMIFS($T$8:$T$26,$S$8:$S$26,B40)) -> 0 | F40: =SUMIFS($X$8:$X$26,$S$8:$S$26,B40) -> 1.66 | G40: =IF(C40=0,0,(B40*$F$33+3+C40)*$F$36+($F$36-1)*$F$31+(2+'Input Data'!$E$18)*$F$30) -> 0 | H40: =IF(AND($E$60<=C40,C40<$E$59),IF(G40=0,0,IF(G40<'Input Data'!$F$4*IF('Input Data'!$J$43="Yes",2,1)-$F$32,1,0)),0) -> 0 | I40: =C40*H40 -> 0
A41: =A39 -> 2 | B41: =$E$28 -> 0.343 | C41: =IF(E41=0,0,$F$36*E41/$F$34+F41) -> 0 | D41: 25000 | E41: =IF('Input Data'!$H$43="No",SUMIFS($J$8:$J$26,$I$8:$I$26,B41),SUMIFS($T$8:$T$26,$S$8:$S$26,B41)) -> 0 | F41: =SUMIFS($X$8:$X$26,$S$8:$S$26,B41) -> 1.72 | G41: =IF(C41=0,0,(B41*$F$33+3+C41)*$F$36+($F$36-1)*$F$31+(2+'Input Data'!$E$18)*$F$30) -> 0 | H41: =IF(AND($E$60<=C41,C41<$E$59),IF(G41=0,0,IF(G41<'Input Data'!$F$4*IF('Input Data'!$J$43="Yes",2,1)-$F$32,1,0)),0) -> 0 | I41: =C41*H41 -> 0
A42: =A39 -> 2 | B42: =$F$28 -> 0.362 | C42: =IF(E42=0,0,$F$36*E42/$F$34+F42) -> 0 | D42: 50000 | E42: =IF('Input Data'!$H$43="No",SUMIFS($J$8:$J$26,$I$8:$I$26,B42),SUMIFS($T$8:$T$26,$S$8:$S$26,B42)) -> 0 | F42: =SUMIFS($X$8:$X$26,$S$8:$S$26,B42) -> 1.81 | G42: =IF(C42=0,0,(B42*$F$33+3+C42)*$F$36+($F$36-1)*$F$31+(2+'Input Data'!$E$18)*$F$30) -> 0 | H42: =IF(AND($E$60<=C42,C42<$E$59),IF(G42=0,0,IF(G42<'Input Data'!$F$4*IF('Input Data'!$J$43="Yes",2,1)-$F$32,1,0)),0) -> 0 | I42: =C42*H42 -> 0
...

Sheet Spring Ass.Length 2
D2: Standard Lift
D3: Drum Size | E3: Max Door Height | F3: Width | G3: Max Weight per Drum | H3: Offset
A4: Wire | B4: 0.343 | D4: D400-96 | E4: 96 | F4: 1.64 | G4: 265 | H4: 3-3/8"
A5: Spring Length | B5: 43 | D5: D400-144 | E5: 144 | F5: 2.63 | G5: 375 | H5: 3-3/8"
A6: Turns | B6: 15.3 | D6: D525-216 | E6: 216 | F6: 3.62 | G6: 750 | H6: 4-3/8"
A7: # of Springs | B7: 2 | D7: D800-384 | E7: 384 | F7: 5.26 | G7: 1100 | H7: 5" *
A8: Space Between Springs | B8: 6
A9: Drum Width | B9: 3.71 | C9: If Center Pickup is added, include the additional drum width in spring assembly length calculation
A10: Door width | B10: 121 | D10: High Lift
D11: Drum Size | E11: Max High-Lift | F11: Width | G11: Max Weight per Drum | H11: Cable Capacity of Flat | I11: Max Door Height | J11: Offset
A12: Assembly Length | B12: =(B4*B6+3+B5)*B7+(B7-1)*B8+2*B9 -> 115.9158 | D12: D400-54 | E12: 54 | F12: 3.03 | G12: 275 | H12: 121 | I12: 174 | J12: 4-3/8"
D13: D525-54 | E13: 54 | F13: 3.66 | G13: 500 | H13: 179 | I13: 234 | J13: 4-3/8"
A14: Length available | B14: =B10-6 -> 115 | C14: =IF(B12<B14,"Ok","Try again") -> Try again | D14: D575-120 | E14: 118 | F14: 3.71 | G14: 500 | H14: 145 | I14: 260 | J14: 5"
A15: Espace free per spring = | B15: =(B10-B12)/B7 -> 2.5421 | C15: =IF(B15<3,"Less than 3''","") -> Less than 3'' | D15: D6375-164 | E15: 164 | F15: 6.09 | G15: 800 | H15: 229 | I15: 393 | J15: 6" *
A16: Extended spring - 2 Rounds = | B16: =B5+B4*(B6-2) -> 47.5619 | D16: D800-120 | E16: 119 | F16: 5.22 | G16: 1100 | H16: 266 | I16: 384 | J16: 6" *
H17: Hi-Lift = | I17: 36
H18: Door Height = | I18: 312
H19: Cable Capacity of Flat | I19: 266
H20: Door Height - High Lift < Capacity of Flat Portion = ? | I20: =IF((I18-I17)<I19,"Yes (Ok)","No") -> No
D22: Vertical Lift
D23: Drum Size | E23: Max Door Height | F23: Width | G23: Max Weight per Drum | H23: Offset
A24: Spring full length | B24: 144 | D24: D850-132 | E24: 132 | F24: 3.33 | G24: 425 | H24: 5"
A25: Spring cut length | B25: 51 | D25: D1100-216 | E25: 216 | F25: 4.29 | G25: 660 | H25: 6"
A26: Qty cuts per full length | B26: =ROUNDDOWN(B24/B25,0) -> 2 | D26: D1350-336 | E26: 336 | F26: 6.75 | G26: 1100 | H26: 7" *
A27: Spring length remaining | B27: =B24-B26*B25 -> 42 | D27: * Tracks Require Angle offset for large Drums
A28: Total springs required | B28: 11
A29: Total full length required | B29: =ROUNDUP(B28/B26,0) -> 6
F34: =B9/1.5 -> 2.4733333 | G34: drum | I34: =F34 -> 2.4733333
F35: =F67 -> 11.927656 | G35: free | I35: =F35+1.25/2+1 -> 13.552656
F36: =B5 -> 43 | G36: spring | I36: =F36 -> 43
F37: 3 | G37: cone | I37: =F37 -> 3
F38: =B4*B6 -> 5.2479 | G38: extension | I38: =F38 -> 5.2479
F39: =F35 -> 11.927656 | G39: free | I39: =F39+1.25/2+1 -> 13.552656
F40: =F36 -> 43 | G40: spring | I40: =F40 -> 43
F41: =F37 -> 3 | G41: cone | I41: =F41 -> 3
F42: =F38 -> 5.2479 | G42: extension | I42: =F42 -> 5.2479
F43: 3 | G43: half coupler | I43: =F43 -> 3 | J43: =SUM(I34:I43) -> 135.07444 | K43: =136-J43 -> 0.92555556
F44: 3 | G44: half coupler | I44: =F44 -> 3
F45: =F40 -> 43 | G45: spring | I45: =F45 -> 43
F46: =F41 -> 3 | G46: cone | I46: =F46 -> 3
...

Sheet Input Data
A1: Legend: | B1: Rev B, Modified | M1: Single Duty | N1: Heavy Duty | O1: Grams
A2: Input | C2: TX Door Model | D2: TX450 | L2: =IF(M2=0,"","#1/2 Hinge") | M2: =IF($D$2="TX380",((ROUND(H5+I5,0)-1)*(J5-1)),0)+IF(D37=0,0,(D37-1)*(J5-1)) -> 0 | O2: =M2*121 -> 0
A3: Formula | D3: Ft | E3: In | F3: Total In | H3: Qty of Sections | J3: Qty of | L3: =IF(M3=0,"","#3/4 Hinge") | M3: =IF(D37=0,0,IF(E38=0,0,1)*(J5-1)) -> 0 | O3: =M3*158 -> 0 | R3: Low Threshold | S3: 8 | T3: lbs (111'-8")
A4: Table | B4: linear | C4: Door Width | D4: 8 | E4: 0 | F4: =D4*12+E4 -> 96 | G4: =F4/2 -> 48 | H4: 21 | I4: 24 | J4: Panels | K4: Panels+/- | L4: =IF(M4+N4=0,"","#1 Hinge") -> #1 Hinge | M4: =IF(D2="TX380",2*E19*(1-E22)*IF(D13=2,1,0),((ROUND(H5+I5,0)-1)*(J5-1)+2*IF(D13=2,1,0)*E19)*(1-E22))+E23*12*(1-E22)-IF(AND(D37<>0,E22=0),M2,0)-IF(AND(D37<>0,E22=0),M3,0) -> 0 | N4: =IF(D2="TX380",2*E19*E22*IF(D13=2,1,0),((ROUND(H5+I5,0)-1)*(J5-1)+2*IF(D13=2,1,0))*E22)+12*E23*E22-IF(E22=1,IF(D2="TX380",0,M2+M3),0) -> 4 | O4: =185*M4+278*N4 -> 1112
A5: Formula | C5: Door Height | D5: 10 | E5: 0 | F5: =D5*12+E5 -> 120 | H5: =VLOOKUP(F5,'Data Tables'!A22:E129,4,FALSE) -> 0 | I5: =VLOOKUP(F5,'Data Tables'!A22:E129,5,FALSE) -> 5 | J5: ='Data Tables'!R51+K5 -> 2 | K5: 0 | L5: =IF(M5+N5=0,"","#2 Hinge") | M5: =2*IF(D13=2,1,0)*E19*(1-E22) -> 0 | N5: =2*IF(D13=2,1,0)*E19*E22 -> 0 | O5: =223*M5+323*N5 -> 0
E6: =IF(H6="","","Cut Top Section of 21'' to") | H6: =IF(VLOOKUP(F5,'Data Tables'!A22:H129,8,FALSE)=0,"",21-VLOOKUP(F5,'Data Tables'!A22:H129,8,FALSE)) | I6: =IF(H6="","","Height") | J6: ℄ Shaft: | K6: =CONCATENATE('Track B.O.M.'!X6,"' - ",'Track B.O.M.'!Y6,"''") -> 21' - 0'' | L6: =IF(M6+N6=0,"","#3 Hinge") -> #3 Hinge | M6: =IF(ROUND($H$5+$I$5,0)-IF($D$13=2,2,0)>=2,2*$E$19,0)*(1-$E$22) -> 0 | N6: =IF(ROUND($H$5+$I$5,0)-IF($D$13=2,2,0)>=2,2*$E$19,0)*$E$22 -> 2 | O6: =228*M6+324*N6 -> 648
C7: Lift Type | D7: Vertical Lift | G7: Total | H7: =IF(I7="",0,VLOOKUP(F5,'Data Tables'!A22:I129,9,FALSE)) -> 0 | I7: Sections of 21'' | L7: =IF(M7+N7=0,"","#4 Hinge") -> #4 Hinge | M7: =IF(ROUND($H$5+$I$5,0)-IF($D$13=2,2,0)>=3,2*$E$19,0)*(1-$E$22) -> 0 | N7: =IF(ROUND($H$5+$I$5,0)-IF($D$13=2,2,0)>=3,2*$E$19,0)*$E$22 -> 2 | O7: =232*M7+339*N7 -> 678
C8: =IF(D7="High Lift","High Lift","") | D8: 45 | E8: U.S.T.: | F8: =IF('Track B.O.M.'!H8="N/A","N/A",CONCATENATE('Track B.O.M.'!H8,"' - ", CEILING('Track B.O.M.'!I8,0.5),"''")) -> N/A | J8: Modified CL Shaft Elev (INCH) | K8: 0 | L8: =IF(M8+N8=0,"","#5 Hinge") -> #5 Hinge | M8: =IF(ROUND($H$5+$I$5,0)-IF($D$13=2,2,0)>=4,2*$E$19,0)*(1-$E$22) -> 0 | N8: =IF(ROUND($H$5+$I$5,0)-IF($D$13=2,2,0)>=4,2*$E$19,0)*$E$22 -> 2 | O8: =238*M8+348*N8 -> 696 | S8: Horizontal Scaling | X8: Vertical Scaling
C9: Drum Model | D9: ='Sub Routine Drums'!S17 -> D850-132 | G9: Cable Diam. & Length | H9: ='Sub Routine Drums'!S18 -> 0.15625 | I9: =IF(E18=0,"x 2 Pcs x","x 3 Pcs x") -> x 2 Pcs x | J9: ='Track B.O.M.'!P11 -> 264 | K9: SS No | L9: =IF(M9+N9=0,"","#6 Hinge") -> #6 Hinge | M9: =IF(ROUND($H$5+$I$5,0)-IF($D$13=2,2,0)>=5,2*$E$19,0)*(1-$E$22) -> 0 | N9: =IF(ROUND($H$5+$I$5,0)-IF($D$13=2,2,0)>=5,2*$E$19,0)*$E$22 -> 2 | O9: =373*M9+373*N9 -> 746 | S9: Door Width | T9: =$F$4 -> 96 | U9: 2.5 | X9: Door Height | Y9: =$F$5 -> 120 | Z9: 2
C10: Offset | D10: ='Sub Routine Drums'!S19 -> 5" | L10: =IF(M10+N10=0,"","#7 Hinge") | M10: =IF(ROUND($H$5+$I$5,0)-IF($D$13=2,2,0)>=6,2*$E$19,0)*(1-$E$22) -> 0 | N10: =IF(ROUND($H$5+$I$5,0)-IF($D$13=2,2,0)>=6,2*$E$19,0)*$E$22 -> 0 | O10: =390*M10+390*N10 -> 0 | S10: End Cap Single | T10: =IF(E19=1,3.5,0) -> 3.5 | U10: =TRUNC(T10*$U$9/$T$9,4) -> 0.0911 | X10: 21" Section High | Y10: 21 | Z10: =IF(H5=0,0,Y10*$Z$9/$Y$9) -> 0
C11: Type of Glaze | D11: U100 | H11: =ROUND((K28+K29+J39)/D12,2) -> 0 | I11: Lbs/ea | L11: =IF(M11+N11=0,"","#8 Hinge") | M11: =IF(ROUND($H$5+$I$5,0)-IF($D$13=2,2,0)>=7,2*$E$19,0)*(1-$E$22) -> 0 | N11: =IF(ROUND($H$5+$I$5,0)-IF($D$13=2,2,0)>=7,2*$E$19,0)*$E$22 -> 0 | O11: =398*M11+398*N11 -> 0 | S11: Double end Cap | T11: =IF(E19=2,5.375,0) -> 0 | U11: =TRUNC(T11*$U$9/$T$9,4) -> 0 | X11: 24" Section High | Y11: 24 | Z11: =IF(I5=0,0,Y11*$Z$9/$Y$9) -> 0.4
C12: =IF(D11<>"U100","Qty","") | D12: 8 | E12: =IF(OR(D11='Data Tables'!Z6,D11='Data Tables'!Z7),"Section(s)",IF(D11="U100","No Glazing","Window(s)")) -> No Glazing | F12: =IF(OR(D11="V130G - 24'' Section",D11="V130G - 21'' Section"),"Glaze:","") | G12: 1/2" Thermopane Glass (10.45) | L12: =IF(M12+N12=0,"","#9 Hinge") | M12: =IF(ROUND($H$5+$I$5,0)-IF($D$13=2,2,0)>=8,2*$E$19,0)*(1-$E$22) -> 0 | N12: =IF(ROUND($H$5+$I$5,0)-IF($D$13=2,2,0)>=8,2*$E$19,0)*$E$22 -> 0 | O12: =409*M12+409*N12 -> 0 | S12: End Rail | T12: =IF(D37<>0,3.6,0) -> 0 | U12: =TRUNC(T12*$U$9/$T$9,4) -> 0 | X12: End Rail height | Y12: =L48 -> 0 | Z12: =Y12*$Z$9/$Y$9 -> 0 | AC12: 2.25
C13: Track Size | D13: 3 | L13: =IF(M13+N13=0,"","#10 Hinge") | M13: =IF(ROUND($H$5+$I$5,0)-IF($D$13=2,2,0)>=9,2*$E$19,0)*(1-$E$22) -> 0 | N13: =IF(ROUND($H$5+$I$5,0)-IF($D$13=2,2,0)>=9,2*$E$19,0)*$E$22 -> 0 | O13: =420*M13+420*N13 -> 0 | S13: End Rail Built Up | T13: =IF(M49<>0,2.25,0) -> 0 | U13: =TRUNC(T13*$U$9/$T$9,4) -> 0 | X13: Male & Female | Y13: =IF(D37<>0,1.25,0) -> 0 | Z13: =Y13*$Z$9/$Y$9 -> 0 | AC13: 3.6
C14: Shaft Coupler (Qty) | D14: 1 | E14: =IF(E15=0,"Shaft Length:","Shaft prep. for electric oper.:") -> Shaft Length: | H14: =IF(D14=0,"1 PC x","2 PCS x") -> 2 PCS x | I14: =IF(D14=0,(F4+12+E15*6+E16*12-E17*12),IF(D14=1,(F4+12+E15*6+E16*12-E17*12)/2,IF(D14=2,(F4+12+E15*6+E16*12-E17*12-I15)/2,IF(D14=3,(F4+12+E15*6+E16*12-E17*12-I15*2)/2)))) -> 54 | J14: =CONCATENATE("(",TRUNC(I14/12,0),"'-",I14-TRUNC(I14/12,0)*12,"'')") -> (4'-6'') | L14: =IF(M14+N14=0,"","#11 Hinge") | M14: =IF(ROUND($H$5+$I$5,0)-IF($D$13=2,2,0)>=10,2*$E$19,0)*(1-$E$22) -> 0 | N14: =IF(ROUND($H$5+$I$5,0)-IF($D$13=2,2,0)>=10,2*$E$19,0)*$E$22 -> 0 | O14: =435*M14+435*N14 -> 0 | S14: Center Rail | T14: =IF(D37<>0,2.64,0) -> 0 | U14: =TRUNC(T14*$U$9/$T$9,4) -> 0 | V14: =U14/2 -> 0 | AC14: 46.05
C15: Prep. Shaft for elect. oper | D15: No | E15: =IF(D15="Yes",1, IF(D15="No",0,"The value entered is not valid")) -> 0 | G15: =IF(D14=2,"Center Shaft 1 PC x",IF(D14=3,"Center Shaft 2 PCS x","")) | I15: =IF(D14=2,CEILING(F4/3,1),IF(D14=3,CEILING(F4/4,0.5),0)) -> 0 | J15: =IF(D14>1,CONCATENATE(TRUNC(I15/12,0),"'-",I15-TRUNC(I15/12,0)*12,"''"),"") | L15: =IF(M15+N15=0,"","#12 Hinge") | M15: =IF(ROUND($H$5+$I$5,0)-IF($D$13=2,2,0)>=11,2*$E$19,0)*(1-$E$22) -> 0 | N15: =IF(ROUND($H$5+$I$5,0)-IF($D$13=2,2,0)>=11,2*$E$19,0)*$E$22 -> 0 | O15: =455*M15+455*N15 -> 0 | R15: Center Rail # | S15: 1 | T15: =L65 | U15: =IF(T15="","",TRUNC(T15*$U$9/$T$9,4)) | X15: Section 21" | Y15: =IF(D11="V130G - 21'' Section",H5-D12,H5) -> 0 | Z15: =Y15*Z10 -> 0 | AC15: 3.6
C16: Low Head Room | D16: =IF(OR(D7="Low Head Room Front Mount",D7="Low Head Room Rear Mount"),"Yes","No") -> No | E16: =IF(D16="Yes",1, IF(D16="No",0,"The value entered is not valid")) -> 0 | I16: ℄ Spring Pad offset from door opening: | J16: =IF(D14=2,(F4-I15)/2,IF(D14=3,(F4/4),"")) | L16: =IF(M16+N16=0,"","#13 Hinge") | M16: =IF(($H$5+$I$5)>=12,2*$E$19*(1-$E$22)*(($H$5+$I$5)-11),0) -> 0 | N16: =IF(($H$5+$I$5)>=12,2*$E$19*E22*($H$5+$I$5-11),0) -> 0 | O16: =575*M16+575*N16 -> 0 | R16: Center Rail # | S16: =IF(S15<$J$5-1,S15+1,"") | T16: =L66 | U16: =IF(T16="","",TRUNC(T16*$U$9/$T$9,4)) | X16: Section 24" | Y16: =IF(D11="V130G - 24'' Section",I5-D12,I5) -> 5 | Z16: =Y16*Z11 -> 2 | AC16: 1
C17: LHR Inside Pick-up | D17: No | E17: =IF(D17="Yes",1, IF(D17="No",0,"The value entered is not valid")) -> 0 | F17: =IF(E18>=1,"Consider additional drum width in spring assembly length","") | L17: =CONCATENATE(D13,"'' ",IF(E16=1,"LHR Top Bracket",IF(M14+N14+M15+N15+M16+N16=0,"Top Bracket","Top Bracket EXTENDED"))) -> 3'' Top Bracket | M17: =2*E19 -> 2 | O17: =IF(E16=1,226*M17,IF(M14+N14+M15+N15+M16+N16=0,312*M17,411*M17)) -> 624 | R17: Center Rail # | S17: =IF(S16<$J$5-1,S16+1,"") | T17: =L67 | U17: =IF(T17="","",TRUNC(T17*$U$9/$T$9,4)) | X17: End Rail Height | Y17: =D12 -> 8 | Z17: =Y17*Z12 -> 0 | AC17: 33
A18: Center Pickup | D18: =IF(E18>=1,"Yes","No") -> No | E18: =IF(SUM(K27:K39)>2200,ROUNDUP(SUM(K27:K39)/1100,0)-2,0) -> 0 | F18: Enforce Double or Triple End Cap & Hinges → | L18: =IF(E25=1,"Safety Bottom Bracket",IF(AND(E16=1,E17=0),"LHR Bottom Bracket",IF(E24=1,"BB2 Bottom Bracket","EZ123 Bottom Bracket"))) -> EZ123 Bottom Bracket | M18: 2 | O18: =IF(E25=1,IF(D13=2,1803*M18,3112*M18),IF(AND(E16=1,E17=0),IF(D13=2,778*M18,2370*M18),IF(E24=1,412*M18,785*M18))) -> 1570 | R18: Center Rail # | S18: =IF(S17<$J$5-1,S17+1,"") | T18: =L68 | U18: =IF(T18="","",TRUNC(T18*$U$9/$T$9,4)) | X18: Male & Female | Y18: =2*D12 -> 16 | Z18: =Y18*Z13 -> 0 | AC18: 1
C19: Double End Cap & Hinges | D19: no | E19: =IF(D19="No",1+IF(I19="Double",1,IF(I19="Triple",2,0)),IF(D19="Yes",2+IF(I19="Triple",1,0))) -> 1 | I19: No | L19: =IF(M19=0,"","2''L/S") | M19: =IF(E19=2,ROUND(H5+I5,0)*2,0)*IF(D13=2,1,0)+2*IF(D13=2,1,0)*E16-IF(AND(D13=2,E17=1,E19=2,OR(D7='Data Tables'!T4,D7='Data Tables'!T5)),2,0) -> 0 | O19: =207*M19 -> 0 | R19: Center Rail # | S19: =IF(S18<$J$5-1,S18+1,"") | T19: =L69 | U19: =IF(T19="","",TRUNC(T19*$U$9/$T$9,4)) | AC19: 3.6
C20: Double End Framing for V130G | D20: =IF(AND(OR(D11='Data Tables'!Z6,D11='Data Tables'!Z7),F4>=14*12+2),"Yes","No") -> No | E20: =IF(D20="Yes",1,IF(I20="Yes",1,0)) -> 0 | H20: Enforce Double End Framing | I20: No | J20: =IF(AND(OR(D11='Data Tables'!Z6,D11='Data Tables'!Z7),OR(D47>0,D48>0,D49>0,D50>0),F4>146),"Yes",IF(AND(OR(D11='Data Tables'!Z6,D11='Data Tables'!Z7),F4>206),"Yes","No")) -> No | L20: =IF(M20=0,"","2'' S/S") | M20: =IF(E19=2,2,(ROUND(H5+I5,0)+1)*2)*IF(D13=2,1,0)-2*IF(D13=2,1,0)*E16+IF(AND(D13=2,E17=1,E19=2,OR(D7='Data Tables'!T4,D7='Data Tables'!T5)),2,0) -> 0 | O20: =158*M20 -> 0 | R20: Center Rail # | S20: =IF(S19<$J$5-1,S19+1,"") | T20: =L70 | U20: =IF(T20="","",TRUNC(T20*$U$9/$T$9,4)) | Y20: Total: | Z20: =SUM(Z15:Z18) -> 2 | AC20: 46.05
C21: End Cap Gauge | D21: 20 | E21: =IF(OR(D21=20, D21=16),D21,"The value entered is not valid") -> 20 | L21: =IF(M21=0,"","3'' L/S") | M21: =IF(E19=2,ROUND(H5+I5,0)*2,0)*IF(D13=3,1,0)+2*IF(D13=3,1,0)*(E16-E17)-IF(AND(D13=3,E17=1,E19=2,OR(D7='Data Tables'!T4,D7='Data Tables'!T5)),2,0) -> 0 | O21: =363*M21 -> 0 | R21: Center Rail # | S21: =IF(S20<$J$5-1,S20+1,"") | T21: =L71 | U21: =IF(T21="","",TRUNC(T21*$U$9/$T$9,4)) | Y21: Difference | Z21: =Z20-Z9 -> 0 | AC21: 3.6
C22: Heavy Duty Hinges | D22: Yes | E22: =IF(D22="Yes",1, IF(D22="No",0,"The value entered is not valid")) -> 1 | L22: =IF(M22=0,"","3'' S/S") -> 3'' S/S | M22: =IF(E19=2,2,(ROUND(H5+I5,0)+1)*2)*IF(D13=3,1,0)-2*IF(D13=3,1,0)*(E16-E17)+IF(AND(D13=3,E17=1,E19=2,OR(D7='Data Tables'!T4,D7='Data Tables'!T5)),2,0) -> 12 | O22: =308*M22 -> 3696 | R22: Center Rail # | S22: =IF(S21<$J$5-1,S21+1,"") | T22: =L72 | U22: =IF(T22="","",TRUNC(T22*$U$9/$T$9,4)) | AC22: 2.25
C23: Man Door | D23: No | E23: =IF(D23="Yes",1, IF(D23="No",0,"The value entered is not valid")) -> 0 | H23: 120 | I23: 2 Hat Strut | L23: Step Kit | M23: 1 | O23: =M23*(116+80+359+50) -> 605 | R23: Center Rail # | S23: =IF(S22<$J$5-1,S22+1,"") | T23: =L73 | U23: =IF(T23="","",TRUNC(T23*$U$9/$T$9,4)) | AC23: =SUM(AC12:AC22) -> 146
C24: Enforce EZ123 Botom Bracket | D24: No | E24: =IF(D24="Yes",0, IF(D24="No",IF(AND(D13=2,K27+K28+K29+K31+K32+K33+K35+J39+K36+K37+K38+K39<300),1,0))) -> 0 | L24: Tek Screws | M24: =24+4*(SUM(M2:M18)+SUM(N4:N16)) -> 88 | O24: =6*M24 -> 528 | R24: Center Rail # | S24: =IF(S23<$J$5-1,S23+1,"") | T24: =L74 | U24: =IF(T24="","",TRUNC(T24*$U$9/$T$9,4))
C25: Shear Type Safety Bottom Bracket | D25: No | E25: =IF(D25="Yes",1,IF(D25="No",0,"The value entered is not valid")) -> 0 | F25: =IF(E25=1,IF(D13=3,"Added 10'' to Clable Length","Added 4'' to Clable Length"),"") | L25: Pull Rope #10 | M25: =IF(ROUND(F5/12,0)-5<5,5,ROUND(F5/12,0)-5) -> 5 | N25: No Pull Rope if Chain Hoist | R25: Center Rail # | S25: =IF(S24<$J$5-1,S24+1,"") | T25: =L75 | U25: =IF(T25="","",TRUNC(T25*$U$9/$T$9,4))
C26: Car Keyed Lock System | D26: No | E26: =IF(D26="Double",2,IF(D26="Single",1,IF(D26="No",0,"The value entered is not valid"))) -> 0 | K26: Lbs | L26: ↓Calculated Weight
C27: Top Astragal & Retainer | D27: =IF(F4>=18*12+0,"Yes","No") -> No | E27: =IF(D27="Yes",1,IF(F27="Yes",1,0)) -> 0 | F27: No | G27: Enforce Top Astragal & Retainer | K27: =ROUND((SUMIFS('Data Tables'!C2:C6,'Data Tables'!A2:A6,D2)*(H7-IF(E37=21,D37,0))+SUMIFS('Data Tables'!D2:D6,'Data Tables'!A2:A6,D2)*(I5-IF(E37=24,D37,0)))*F4/12+E73+G73+F86,0)+K39 -> 193 | L27: Steel | P27: 134
D28: +/- | E28: Total ↓ | F28: Lbs | K28: =IF(OR(D2="TX450",D2="TX450-20",D2="TX500",D2="TX500-20"),ROUND(IF(OR(D11="V130G - 24'' Section",D11="V130G - 21'' Section"),O58,0),0),0)+J39 -> 0 | L28: Aluminum | M28: ↓Actual Weight | P28: 44 | S28: Window W | T28: 18 | U28: =TRUNC(T28*$U$9/$T$9,4) -> 0.4687 | X28: Window H | Y28: 8 | Z28: =TRUNC(Y28*$Z$9/$Y$9,4) -> 0.1333
B29: Low Thresold (Mandoor) | C29: =IF(I23="1 Thresold",1,0) -> 0 | D29: 0 | E29: =C29+D29 -> 0 | F29: =E29*(F4/12)*'Data Tables'!AA41 -> 0 | J29: Lbs | K29: =IF(OR(D2="TX450",D2="TX450-20",D2="TX500",D2="TX500-20"),ROUND(IF(OR(D11="V130G - 24'' Section",D11="V130G - 21'' Section"),IF(D60=J5,D64*D37,"Review Glazing"),0),0),0) -> 0 | L29: Glazing | M29: 597 | O29: =K27+K28+K29+K36+K37+K38+K41 -> 193 | P29: 108 | S29: Other Dimension W | U29: =TRUNC(T29*$U$9/$T$9,4) -> 0 | X29: Other Dimension H | Y29: 1.25 | Z29: =TRUNC(Y29*$Z$9/$Y$9,4) -> 0.0208
B30: 20ga Strut | C30: 0 | D30: 1 | E30: =C30+D30 -> 1 | F30: =E30*(F4/12)*'Data Tables'!AB35 -> 6.32 | H30: Strut Clip (Pcs) | I30: =IF(E30=0,"",(J5+1+2*(E19-1))*E30) -> 3 | J30: =IF(E30=0,0,I30*'Data Tables'!AA40) -> 0.11448488 | K30: =ROUND(SUM(O2:O24)/454,0) -> 24 | L30: Hardware | M30: =ROUND(K30,0) -> 24 | N30: H/W | P30: 23
B31: Std 16ga Hat Strut | C31: 0 | D31: 1 | E31: =C31+D31 -> 1 | F31: =IF(B31="Std 16ga Hat Strut",E31*(F4/12)*'Data Tables'!AB36,E31*(F4/12)*'Data Tables'!AB37) -> 8.4 | H31: Strut Clip (Pcs) | I31: =IF(E31=0,"",(J5+1+2*(E19-1))*E31) -> 3 | J31: =IF(E31=0,0,I31*'Data Tables'!AA40) -> 0.11448488 | K31: =ROUND(IF(E26=0,0,IF(E26=1,(F4/12)/2*'Data Tables'!H4+'Data Tables'!H2,IF(E26=2,F4/12*'Data Tables'!H4+'Data Tables'!H3,0))),0) -> 0 | L31: Car k. Lock Syst | M31: =K31 -> 0 | N31: Car k. Lock System | P31: =SUM(P27:P30) -> 309 | T31: 4" Exhaust Port Diam | U31: 4 | V31: =U31*Z9/Y9 -> 0.066666667
B32: Z Strut | C32: 0 | D32: 1 | E32: =C32+D32 -> 1 | F32: =IF(E32=0,0,E32*I32*'Data Tables'!AA54) -> 19.568 | H32: Z Strut (Length) | I32: =IF(E32+E33=0,"",F4/12) -> 8 | J32: =IF(E32+E33=0,0,(E32+E33)*I32*'Data Tables'!AA54) -> 19.568 | K32: =ROUND(F30+J30,0) -> 6 | L32: 20ga Struts | M32: =ROUND(K32,0) -> 6 | N32: 20ga Struts | T32: Exhaust Port 3" Diam | U32: 3 | V32: =U32*Z9/Y9 -> 0.05
B33: Additional T & B Z Strut | C33: 0 | D33: 0 | E33: =C33+D33 -> 0 | F33: =IF(E33=0,0,E33*I33*'Data Tables'!AA54) -> 0 | H33: Connector (Pcs) | I33: =IF(E32+E33=0,"",ROUNDDOWN((F4/12/10)-1,0)*(E32+E33)) -> 0 | J33: =IF(E32+E33=0,0,I33*'Data Tables'!AA54) -> 0 | K33: =ROUND(F31+J31,0) -> 9 | L33: 16ga Struts | M33: =ROUND(K33,0) -> 9 | N33: 16ga Struts | Q33: 2.78
B34: 34"x16" Thermopane | C34: =IF(D11='Data Tables'!Z3,D12,0) -> 0 | D34: 0 | E34: =C34+D34 -> 0 | F34: =E34*'Data Tables'!AP56 -> 0 | H34: Z Straps Bended(Pcs) | I34: =IF(E32=0,"",(J5+1)*E32) -> 3 | J34: =IF(E32=0,0,I34*'Data Tables'!AA55) -> 5.0166 | K34: =F29 -> 0 | L34: Low Thresold | M34: 0 | N34: Low Thresold, included in V130G | Q34: 4.87
B35: 24"x12" Thermopane | C35: =IF(D11='Data Tables'!Z4,D12,0) -> 0 | D35: 0 | E35: =C35+D35 -> 0 | F35: =E35*'Data Tables'!AO56 -> 0 | H35: Z Straps Straight(Pcs) | I35: =IF(E33=0,"",(J5+1)*E33) | J35: =IF(E33=0,0,I35*'Data Tables'!AA56) -> 0 | K35: =ROUND(J32+J33+J34+J35,0) -> 25 | L35: Z Struts | M35: =ROUND(K35,0) -> 25 | N35: Z Struts | Q35: 0.31 | T35: # of Windows per section | U35: 1
B36: 18"x8" Thermopane | C36: =IF(D11='Data Tables'!Z5,D12,0) -> 0 | D36: 0 | E36: =C36+D36 -> 0 | F36: =E36*'Data Tables'!AN56 -> 0 | K36: =ROUND(F34,0) -> 0 | L36: 34"x16" Thermo Windows | M36: 0 | N36: T-Bar, included in V130G | Q36: =SUM(Q33:Q35) -> 7.96 | T36: Space between windows | U36: =(F4-U35*24)/(U35+1) -> 36 | V36: =(U9-D12*U28)/(D12+1) -> -0.13884444
C37: # Sections V130G | D37: =IF(OR(D11="V130G - 24'' Section",D11="V130G - 21'' Section"),D12,0) -> 0 | E37: =IF(D11='Data Tables'!Z6,24,IF(D11='Data Tables'!Z7,21,0)) -> 0 | F37: Height | K37: =ROUND(F35,0) -> 0 | L37: 24"x12" Thermo Windows | M37: 0 | N37: V-Strut, included in V130G
C38: Build In Strut for V130G | D38: =IF(AND(D37>0,F4>=14*12+2,OR(D47>0,D48>0,D49>0,D50>0)),"Yes",IF(AND(D37>0,F4>=18*12+0),"Yes","No")) -> No | E38: =IF(D38="Yes",1,IF(F38="Yes",1,0)) -> 0 | F38: No | G38: Enforce Build In Strut for V130G | K38: =F36 -> 0 | L38: 18"x8" Thermo Windows | M38: =IF(OR(M29="", M29=0),"",SUM(M29:M37)) -> 661 | N38: Total
C39: T-Bar for V130G | D39: =IF(AND(F4>=18*12+0,OR(D11='Data Tables'!Z6,D11='Data Tables'!Z7),OR(D47>0,D48>0,D49>0,D50>0)),"Yes",IF(AND(F4>=20*12+1,OR(D11='Data Tables'!Z6,D11='Data Tables'!Z7)),"Yes","No")) -> No | E39: =IF(D39="Yes",1,IF(F39="Yes",1,0)) -> 0 | F39: No | G39: Enforce T-Bar for V130G | K39: =ROUND(19*E23,0) -> 0 | L39: Man Door | M39: =IF(M38="","",(M38-K40)/M38) -> 0.61119516 | N39: =IF(M38="","",CONCATENATE(ROUND(M38-K40,2)," Lbs")) -> 404 Lbs | S39: Interpolation
K40: =SUM(K27:K38)+K41 -> 257 | L40: Total | M40: (Actual - Calculated) | S40: x1 | T40: 8.16 | U40: x2 | V40: 6.97
...

Sheet Track B.O.M.
D1: TRACK COMPONENTS AND HARDWARE | E1: Rev | F1: H
A2: FT | B2: IN
A3: ='Input Data'!D4 -> 8 | B3: ='Input Data'!E4 -> 0 | C3: =A3*12+B3 -> 96 | D3: Door Width | K3: Shop Drawing Dimensions
A4: ='Input Data'!D5 -> 10 | B4: ='Input Data'!E5 -> 0 | C4: =A4*12+B4 -> 120 | D4: Door Height | K4: Track Type | N4: ='Sub-Routine for U.S.T. and misc'!C17 -> VERTICAL LIFT
C5: ='Input Data'!D13 -> 3 | D5: Track Size (2" or 3") | K5: High Lift | N5: =IF(C7=2,C8,"N/A") -> N/A | P5: =IF(C7=2,ROUNDDOWN(N5/12,0),"N/A") -> N/A | Q5: =IF(C7=2,N5-P5*12,"N/A") -> N/A | U5: Floor to Ceiling (DH + HR) | V5: =C4+N7 -> 258 | X5: =INT(V5/12) -> 21 | Y5: =V5-X5*12 -> 6 | Z5: =X5*12+Y5 -> 258 | AA5: =Z5*25.4 -> 6553.2 | AB5: mm
C6: 0 | D6: Track Material (0 Std, 1 Powder Coated) | H6: Modified CL Shaft Elev (Inch) | I6: ='Input Data'!K8 -> 0 | K6: Center Line of Shaft | N6: =IF(OR(I6=0,I6=""),'Sub-Routine for U.S.T. and misc'!C19,I6-C4) -> 132 | P6: =INT(N6/12) -> 11 | Q6: =(N6/12-P6)*12 -> 0 | U6: Bottom to CL Shaft1 | V6: =C4+N6 -> 252 | X6: =INT(V6/12) -> 21 | Y6: =V6-X6*12 -> 0
C7: =IF('Input Data'!D7="Standard Lift 15'' Radius",0,IF('Input Data'!D7="Standard Lift 12'' Radius",0,IF(OR('Input Data'!D7="Low Head Room Front Mount",'Input Data'!D7="Low Head Room Rear Mount"),1,IF('Input Data'!D7="High Lift",2,IF('Input Data'!D7="Vertical Lift",3,"Error"))))) -> 3 | D7: Track Type (0-Std, 1-LHR, 2-HL, 3-VL) | F7: IN | H7: FT | I7: IN | K7: Headroom (min) | N7: =IF(I6=0,'Sub-Routine for U.S.T. and misc'!C20,I6-C4+4) -> 138 | P7: =INT(N7/12) -> 11 | Q7: =(N7/12-P7)*12 -> 6
C8: ='Input Data'!D8 -> 45 | D8: =IF(C7=2,"High Lift (in)=","") | E8: U.S.T.= | F8: =IF(C7=1,C4,'Sub-Routine for U.S.T. and misc'!C18) -> 0 | H8: =IF(C7=3,"N/A",INT(F8/12)) -> N/A | I8: =IF(C7=3,"N/A",(F8/12-H8)*12) -> N/A | K8: Backroom | N8: ='Sub-Routine for U.S.T. and misc'!C21 -> 18 | P8: =INT(N8/12) -> 1 | Q8: =(N8/12-P8)*12 -> 6 | U8: CL Shaft 2 (Tandem Shaft) offset | V8: 12
C9: =IF('Input Data'!D7="Low Head Room Front Mount",1,IF('Input Data'!D7="Low Head Room Rear Mount",0,"")) | D9: =IF(C7=1,"Front Mount = 1, Rear Mount = 0","") | K9: Side Room | N9: =IF(C14=0,'Sub-Routine for U.S.T. and misc'!C23,'Sub-Routine for U.S.T. and misc'!C25) -> 4.25 | U9: CL Shaft 2 (Tandem Shaft) Elev | V9: =V6+V8 -> 264 | X9: =INT(V9/12) -> 22 | Y9: =V9-X9*12 -> 0
C10: ='Input Data'!E17 -> 0 | D10: 1 Inside Pick Up, 0 Outside Pick Up, | K10: Center Post | N10: =IF(C14=0,'Sub-Routine for U.S.T. and misc'!C24,'Sub-Routine for U.S.T. and misc'!C26) -> 8.5 | U10: Tandem Shaft Headroom | V10: =N7+V8 -> 150 | W10: → | X10: =INT(V10/12) -> 12 | Y10: =V10-X10*12 -> 6
C11: =IF('Input Data'!D7='Data Tables'!T2,'Data Tables'!W2,IF('Input Data'!D7='Data Tables'!T3,'Data Tables'!W3,IF('Input Data'!D7='Data Tables'!T6,'Data Tables'!W6,IF('Input Data'!D7='Data Tables'!T4,'Data Tables'!W4,IF('Input Data'!D7='Data Tables'!T5,'Data Tables'!W5,"N/A"))))) -> N/A | D11: Radius (15 or 12 Degrees) | I11: Drum #: | J11: ='Sub Routine Drums'!U17 -> 10 | K11: Cable Length | N11: ='Input Data'!H9 -> 0.15625 | O11: =CONCATENATE("x 2 Pcs",IF(C6=1," S.S.","")) -> x 2 Pcs | P11: =IF(I6=0,C4+N6,I6)+'Cable Length'!G42+IF(AND(C7=1,C9=1),0,0)*(1-C10)+IF(AND(C7=1,C9=0),C4+15.5,0)+IF(AND(C7=3,I6=0),0,0)+IF('Input Data'!D13=3,'Input Data'!E25*10,'Input Data'!E25*4) -> 264 | U11: Floor to Ceiling (DH + HR) for Tandem | V11: =N7+C4+12 -> 270 | X11: =INT(V11/12) -> 22 | Y11: =(V11/12-X11)*12 -> 6
C12: 3 | D12: Pulley Diameter | G12: 10 | I12: Offset: | J12: =SUMIFS(M29:M40,K29:K40,J11) -> 5 | K12: in | M12: Diameter depend on drum & door weight
C13: 0 | D13: Pitch (Degrees) - (No additional calculations yet) | M13: If Powder Coated then Diam. = 5/32" SS
C14: 1 | D14: Mount Type (0 Angle, 1 Bracket)
C15: 1 | D15: Frame Type (0 Steel, 1 Wood)
C16: 0 | D16: Reinforced Horizontal Angle (1 Yes, 0 No) | M16: =CEILING(SQRT(POWER(C4+'Input Data'!D13,2)+POWER(C11+C12/2,2))+SQRT(POWER(C11+C12/2-'Input Data'!D10,2)+POWER(IF('Input Data'!D13=2,6.5,7.5),2))+PI()*'Sub Routine Drums'!S22*270/360+1,0.5) -> #VALUE! | N16: LHR Front Mount (New Formula)
C17: =IF(OR(J11=4,J11=8, J11=9,J11=12),1,0) -> 0 | D17: Angle offset for Large Drums (1 Yes, 0 No) | E17: (Yes when Drum is: D800-384, D800-120, Di350-336 or D6375-164) | M17: =CEILING(SQRT(POWER(C4+'Input Data'!D13,2)+POWER(C11+C12/2,2))+C4-C11+'Sub Routine Drums'!S22+PI()*'Sub Routine Drums'!S22*90/360+1,0.5) -> #VALUE! | N17: LHR Rear Mount (New Formula)
C18: Qty | D18: Track Components | E18: Length (in) | F18: Carriage Bolt | G18: Track Bolt | I18: FT | J18: IN | K18: Cut Vertical Angle from
C19: 2 | D19: =CONCATENATE("Track Vertical Section",IF(C6=1," - P. Coated","")) -> Track Vertical Section | E19: =IF(C7=0,C4-8,IF(C7=1,C4-15,IF(C7=2,C4-8, IF(C7=3,C4-IF(C4<=11*12,8,IF(C4<=18*12,11,13.5)),0)))) -> 112 | F19: =1*I19*12/24*C19 -> 9 | G19: =1*C19 -> 2 | I19: =INT(E19/12) -> 9 | J19: =(E19/12-I19)*12 -> 4
C20: =IF(OR(C7=2,C7=3),2,0) -> 2 | D20: =IF(OR(C7=2,C7=3),CONCATENATE("Track Vertical Extension",IF(C6=1," - P. Coated","")),"") -> Track Vertical Extension | E20: =IF(C7=2,C8-C11+8,IF(C7=3,C4*2+12+8-E19,0)) -> 148 | I20: =INT(E20/12) -> 12 | J20: =(E20/12-I20)*12 -> 4
C21: =IF(C14=0,2,0) -> 0 | D21: =IF(C14=0,"Vertical Angle Mounting","") | E21: =IF(C14=0,E19-11,0) -> 0 | I21: =IF(C14=0,INT(E21/12),0) -> 0 | J21: =ROUND((E21/12-I21)*12,0) -> 0 | K21: =IF(E21=0,0,IF(J21>1,EVEN(I21)+1,ODD(I21))) -> 0 | L21: =IF(E21=0,0,1) -> 0
C22: =IF(C7=3,0,2) -> 0 | D22: =IF(C7=3,"",CONCATENATE("Track Horizontal Section",IF(C6=1," - P. Coated",""))) | E22: =I22*12 -> 0 | I22: =IF(C7=3,0,IF(EVEN(IF(B4=0,A4-IF(I20>2,I20,0),A4+1-IF(I20>2,I20,0)))<8,8,EVEN(IF(B4=0,A4-IF(I20>2,I20,0),A4+1-IF(I20>2,I20,0))))) -> 0 | J22: 0 | K22: minus Ft of Extension if > 2' | N22: Minimum Length = 8 Ft
C23: =IF(C7=1,2,0) -> 0 | D23: =IF(C7=1,CONCATENATE("Low Head Room Track Horizontal Section",IF(C6=1," - P. Coated","")),"") | E23: =IF(C7=1,I22*12,0) -> 0 | F23: =4*E23/24*C23 -> 0 | G23: =2*C23 -> 0 | I23: =IF(C7=1,I22,0) -> 0 | J23: 0
C24: =C22-C23 -> 0 | D24: =IF(OR(C7=3,C7=1),"","Horizontal Angle Support") | E24: =IF(OR(C7=0,C7=2),E22+14,0) -> 0 | F24: =2*E22/24*C24 -> 0 | G24: =2*C24 -> 0 | I24: =IF(C7=3,0,I22+1) -> 0 | J24: =IF(C7=3,0,J22+2) -> 0
C25: =IF(C16=1,2,0) -> 0 | D25: =IF(C7=3,"",IF(C16=1,"Reincorced Horizontal Angle","")) | E25: =(E22+14-24)*C16 -> 0 | I25: =INT(E25/12) -> 0 | J25: =ROUND((E25/12-I25)*12,0) -> 0
C26: =IF($C$7=3,2,0) -> 2 | D26: =IF($C$7=3,"1-1/4 x 1-1/4 x 50.5'' Flag Angle","") -> 1-1/4 x 1-1/4 x 50.5'' Flag Angle | G26: =4*C26 -> 8
C27: =IF($C$7=3,2,0) -> 2 | D27: =IF($C$7=3,"1-1/4 x 1-1/4 x 14'' Top Angle","") -> 1-1/4 x 1-1/4 x 14'' Top Angle | F27: =1*C27 -> 2 | G27: =1*C27 -> 2
C28: =IF($C$7=3,2,0) -> 2 | D28: =IF($C$7=3,"1 Slot Splice Plate 11-1/4'' Long","") -> 1 Slot Splice Plate 11-1/4'' Long | G28: =1*C28 -> 2 | K28: # | L28: Drum | M28: Offset | N28: Cable Diam.
C29: =IF($C$7=3,2,0) -> 2 | D29: =IF($C$7=3,"1 Slot Splice Plate 9-1/4'' Long","") -> 1 Slot Splice Plate 9-1/4'' Long | G29: =1*C29 -> 2 | I29: =116-118.5 -> -2.5 | J29: Std. Lift | K29: 1 | L29: D400-96 | M29: 3.375 | N29: 0.125 | O29: 0.125
C30: =IF($C$7=3,IF(AND($C$4>0,$C$4<169),2,0),0) -> 2 | D30: =IF(C30=0,"",IF($C$7=3,"#12 Jamb Bracket","")) -> #12 Jamb Bracket | G30: =1*C30 -> 2 | I30: =140-142.5 -> -2.5 | K30: 2 | L30: D400-144 | M30: 3.375 | N30: 0.125 | O30: 0.15625
C31: =IF($C$7=3,IF(AND($C$4>0,$C$4<145),2,0),0) -> 2 | D31: =IF(C31=0,"",IF($C$7=3,"#18 Jamb Bracket","")) -> #18 Jamb Bracket | G31: =1*C31 -> 2 | I31: =120-120.5 -> -0.5 | K31: 3 | L31: D525-216 | M31: 4.375 | N31: 0.15625 | O31: 0.1875
C32: =IF($C$7=3,IF(AND($C$4>144,$C$4<169),2,0),0) -> 0 | D32: =IF(C32=0,"",IF($C$7=3,"#20 Jamb Bracket","")) | G32: =1*C32 -> 0 | I32: =268-269.5 -> -1.5 | K32: 4 | L32: D800-384 | M32: 5 | N32: 0.1875 | O32: 0.25
C33: =IF($C$7=3,IF(AND($C$4>96,$C$4<145),2,0),0) -> 2 | D33: =IF(C33=0,"",IF($C$7=3,"#25 Jamb Bracket","")) -> #25 Jamb Bracket | G33: =1*C33 -> 2 | J33: High Lift | K33: 5 | L33: D400-54 | M33: 4.375 | N33: 0.125 | O33: 0.15625
C34: =IF($C$7=3,IF(AND($C$4>144,$C$4<169),2,0),0) -> 0 | D34: =IF(C34=0,"",IF($C$7=3,"#28 Jamb Bracket","")) | G34: =1*C34 -> 0 | K34: 6 | L34: D525-54 | M34: 4.375 | N34: 0.15625 | O34: 0.1875
C35: =IF($C$7=3,IF(AND($C$4>120,$C$4<145),2,0),0) -> 0 | D35: =IF(C35=0,"",IF($C$7=3,"#30 Jamb Bracket","")) | G35: =1*C35 -> 0 | K35: 7 | L35: D575-120 | M35: 5 | N35: 0.15625 | O35: 0.1875
C36: =IF($C$7=3,IF(AND($C$4>144,$C$4<169),2,0),0) -> 0 | D36: =IF(C36=0,"",IF($C$7=3,"#32 Jamb Bracket","")) | G36: =1*C36 -> 0 | K36: 8 | L36: D6375-164 | M36: 6 | N36: 0.1875 | O36: 0.25
C37: =E23/24 -> 0 | D37: =IF(C37=0,"",IF(C5=2,CONCATENATE("2'' L.H.R. Splice Bracket",IF(C6=1," - P. Coated","")),CONCATENATE("3'' L.H.R. Splice Bracket",IF(C6=1," - P. Coated","")))) | K37: 9 | L37: D800-120 | M37: 6 | N37: 0.1875 | O37: 0.25
C38: =IF(C7=1,2,0) -> 0 | D38: =IF(C38=0,"",IF(C5=2,CONCATENATE("2'' Pulley Plate",IF(C6=1," - P. Coated","")),CONCATENATE("3'' Pulley Plate",IF(C6=1," - P. Coated","")))) | G38: =4*C38 -> 0 | J38: Vert. Lift | K38: 10 | L38: 850-132 | M38: 5 | N38: 0.15625 | O38: 0.1875
C39: =IF(C7=1,2*C10,0) -> 0 | D39: =IF(C39=0,"",IF(C5=2,"2'' Pulley","3'' Pulley")) | K39: 11 | L39: 1100-216 | M39: 6 | N39: 0.15625 | O39: 0.1875
C40: =IF(C7=1,2,0) -> 0 | D40: =IF(C40=0,"","1-1/2 x 1-1/2 x 18'' L.H.R. Angle Extension") | G40: =2*C40 -> 0 | K40: 12 | L40: 1350-336 | M40: 7 | N40: 0.1875 | O40: 0.25
...

Sheet Hardware Box
A1: Door hardware box list and Spring weight
A2: Customer | D2: Work Order | E2: Door
A3: Sample | D3: 9999 | E3: 1/1
B4: In Bag | C4: Installed | E4: ft | F4: in
A5: ='Track B.O.M.'!D52 -> 1/4 x 3/4'' Carriage Bolt | B5: ='Track B.O.M.'!$C$52-'Track B.O.M.'!$F$24 -> 21 | C5: ='Track B.O.M.'!$F$24 -> 0 | D5: Door Width | E5: ='Input Data'!D4 -> 8 | F5: ='Input Data'!E4 -> 0
A6: ='Track B.O.M.'!D53 -> 1/4 x 3/4'' Track Bolt | B6: ='Track B.O.M.'!C53 -> 28 | D6: Door Height | E6: ='Input Data'!D5 -> 10 | F6: ='Input Data'!E5 -> 0
A7: ='Track B.O.M.'!D54 -> 1/4'' Hex Washer Nut | B7: =SUM(B5:B6) -> 49 | C7: ='Track B.O.M.'!$F$24 -> 0 | D7: Track Size | F7: ='Input Data'!$D$13 -> 3
A8: ='Track B.O.M.'!D55 -> 5/16 x 1-5/8'' Washer Lag Screw | B8: ='Track B.O.M.'!C55 -> 42 | D8: Track Radius | E8: ='Input Data'!$D$7 -> Vertical Lift
A9: 5/16 x 3/4 Carriage Bolt | B9: 8 | D9: Hi Lift Length | E9: =IF('Input Data'!$D$7="High Lift", 'Input Data'!$D$8, "NA") -> NA
A10: Key Stock | B10: =2+'Input Data'!$D$14*2 -> 4
A11: Drums Model | B11: {='Input Data'!$D$9:$E$9} -> D850-132 | C11: 0 | D11: {='Input Data'!$L$4:$L$21} -> #1 Hinge | E11: {='Input Data'!$M$4:$M$21} -> 0
A12: ='Input Data'!$C$10 -> Offset | B12: {='Input Data'!$D$10:$E$10} -> 5" | C12: 0 | E12: 0
A13: Spring Plates | B13: See Spring Assembly | D13: #3 Hinge | E13: 0
D14: #4 Hinge | E14: 0
A15: # of Springs | D15: #5 Hinge | E15: 0
A16: Wire size | D16: #6 Hinge | E16: 0
A17: Spring ID | E17: 0
A18: Spring Length | E18: 0
A19: Number of turns | E19: 0
A20: # of Bearing Plates | E20: 0
A21: Coupler | E21: 0
A22: Shaft | E22: 0
E23: 0
A24: {='Input Data'!$H$30:$H$35} -> Strut Clip (Pcs) | B24: {='Input Data'!$I$30:$I$35} -> 3 | D24: 3'' Top Bracket | E24: 2
A25: Strut Clip (Pcs) | B25: 3 | D25: EZ123 Bottom Bracket | E25: 2
A26: Z Strut (Length) | B26: 8 | E26: 0
A27: Connector (Pcs) | B27: 0 | E27: 0
A28: Z Straps Bended(Pcs) | B28: 3 | E28: 0
A29: Z Straps Straight(Pcs) | D29: ='Input Data'!$L$22 -> 3'' S/S | E29: ='Input Data'!$M$22-(E25+E24) -> 8
D30: 3" L/S for SEC | E30: =IF('Input Data'!$M$21<1,4,0) -> 4
A31: ='Input Data'!$G$9 -> Cable Diam. & Length | B31: ='Input Data'!$H$9 -> 0.15625 | C31: ='Input Data'!$I$9 -> x 2 Pcs x | D31: ='Input Data'!$L$23 -> Step Kit | E31: ='Input Data'!$M$23 -> 1
A32: Cable length exact (in) | C32: ='Input Data'!$J$9 -> 264 | D32: ='Input Data'!$L$24 -> Tek Screws | E32: ='Input Data'!$M$24 -> 88
A33: Door Weight | D33: ='Input Data'!$L$25 -> Pull Rope #10 | E33: ='Input Data'!$M$25 -> 5
A34: ='Input Data'!$L$27 -> Steel | B34: ='Input Data'!$K$27 -> 193 | D34: Jamb Brackets & Spring Plates
A35: ='Input Data'!$L$28 -> Aluminum | B35: ='Input Data'!$K$28 -> 0 | D35: ='Track B.O.M.'!D43 -> #5 Angle Bracket | E35: ='Track B.O.M.'!C43 -> 2
A36: ='Input Data'!$L$29 -> Glazing | B36: ='Input Data'!$K$29 -> 0 | D36: ='Track B.O.M.'!D44 -> #6 Angle Bracket | E36: ='Track B.O.M.'!C44 -> 2
A37: ='Input Data'!$L$30 -> Hardware | B37: =('Input Data'!$K$30) -> 24 | D37: ='Track B.O.M.'!D45 -> #7 Angle Bracket | E37: ='Track B.O.M.'!C45 -> 2
A38: ='Input Data'!$L$32 -> 20ga Struts | B38: ='Input Data'!$K$32 -> 6 | D38: ='Track B.O.M.'!D46 -> #8 Angle Bracket | E38: ='Track B.O.M.'!C46 -> 2
A39: ='Input Data'!$L$33 -> 16ga Struts | B39: ='Input Data'!$K$33 -> 9 | D39: ='Track B.O.M.'!D47 | E39: ='Track B.O.M.'!C47 -> 0
A40: ='Input Data'!$L$36 -> 34"x16" Thermo Windows | B40: ='Input Data'!$K$36 -> 0 | D40: ='Track B.O.M.'!D48 | E40: ='Track B.O.M.'!C48 -> 0
...

Sheet Hardware Box Pricing Calculator
A1: Door hardware box list and Spring weight | D1: UPW | F1: LYNX | J1: UPW | L1: LYNX
A2: Customer | H2: Work Order | I2: Door
B4: In Bag | C4: Installed | I4: ft | J4: in
A5: 1/4 x 3/4'' Carriage Bolt | B5: ='Track B.O.M.'!$C$52-'Track B.O.M.'!$F$24 -> 21 | C5: ='Track B.O.M.'!$F$24 -> 0 | D5: 0.1 | E5: =SUM($B5:$C5)*D5 -> 2.1 | F5: 0.1 | G5: =SUM($B5:$C5)*F5 -> 2.1 | H5: Door Width | I5: ='[1]Hardware Box'!$E$5 -> 10 | J5: 0
A6: 1/4 x 3/4'' Track Bolt | B6: ='Track B.O.M.'!C53 -> 28 | D6: 0.1 | E6: =SUM($B6:$C6)*D6 -> 2.8 | F6: 0.1 | G6: =SUM($B6:$C6)*F6 -> 2.8 | H6: Door Height | I6: ='[1]Hardware Box'!$E$6 -> 10 | J6: 0
A7: 1/4'' Hex Washer Nut | B7: =SUM(B5:B6) -> 49 | C7: ='Track B.O.M.'!$F$24 -> 0 | D7: 0.1 | E7: =SUM($B7:$C7)*D7 -> 4.9 | F7: 0.1 | G7: =SUM($B7:$C7)*F7 -> 4.9 | H7: Track Size | J7: 3
A8: 5/16 x 1-5/8'' Washer Lag Screw | B8: ='Track B.O.M.'!C55 -> 42 | D8: 0.25 | E8: =SUM($B8:$C8)*D8 -> 10.5 | F8: 0.25 | G8: =SUM($B8:$C8)*F8 -> 10.5 | H8: Track Radius | I8: ='Input Data'!$D$7 -> Vertical Lift
A9: 5/16 x 3/4 Carriage Bolt | B9: 8 | D9: 0.1 | E9: =SUM($B9:$C9)*D9 -> 0.8 | F9: 0.1 | G9: =SUM($B9:$C9)*F9 -> 0.8 | H9: Hi Lift Length | I9: =IF('Input Data'!$D$7="High Lift", 'Input Data'!$D$8, "NA") -> NA
A10: Key Stock | B10: =2+'Input Data'!$D$14*2 -> 4 | D10: 0.31 | E10: =SUM($B10:$C10)*D10 -> 1.24 | F10: 0.25 | G10: =SUM($B10:$C10)*F10 -> 1
A11: Drums Model | B11: D525-216 | C11: 1 | D11: 29.11 | E11: =C11*D11 -> 29.11 | F11: 15.02 | G11: =C11*F11 -> 15.02 | H11: #1 Hinge | I11: ='[1]Hardware Box'!$E11 -> 4 | J11: 2.35 | K11: =I11*J11 -> 9.4 | L11: 1.26 | M11: =I11*L11 -> 5.04
A12: Centre Bearing Plate | B12: 4.375 | C12: 6 | D12: 8.85 | E12: =C12*D12 -> 53.1 | F12: 18.44 | G12: =C12*F12 -> 110.64 | I12: ='[1]Hardware Box'!$E12 -> 0 | J12: 2.72 | K12: =I12*J12 -> 0 | L12: 1.41 | M12: =I12*L12 -> 0
A13: End Bearing Plate | C13: 6 | D13: 8.85 | E13: =C13*D13 -> 53.1 | F13: 4.32 | G13: =C13*F13 -> 25.92 | H13: #3 Hinge | I13: ='[1]Hardware Box'!$E13 -> 2 | J13: 2.82 | K13: =I13*J13 -> 5.64 | L13: 1.46 | M13: =I13*L13 -> 2.92
A14: Shaft Coupler | D14: 17.47 | H14: #4 Hinge | I14: ='[1]Hardware Box'!$E14 -> 2 | J14: 2.9 | K14: =I14*J14 -> 5.8 | L14: 1.52 | M14: =I14*L14 -> 3.04
A15: # of springs | H15: #5 Hinge | I15: ='[1]Hardware Box'!$E15 -> 2 | J15: 3.04 | K15: =I15*J15 -> 6.08 | L15: 1.58 | M15: =I15*L15 -> 3.16
A16: Wire size | H16: #6 Hinge | I16: ='[1]Hardware Box'!$E16 -> 2 | J16: 3.24 | K16: =I16*J16 -> 6.48 | L16: 1.64 | M16: =I16*L16 -> 3.28
A17: Spring ID | H17: #7 Hinge | I17: ='[1]Hardware Box'!$E17 -> 0 | J17: 3.07 | K17: =I17*J17 -> 0 | L17: 1.7 | M17: =I17*L17 -> 0
A18: Spring Length | H18: #8 Hinge | I18: ='[1]Hardware Box'!$E18 -> 0 | J18: 3.82 | K18: =I18*J18 -> 0 | L18: 1.76 | M18: =I18*L18 -> 0
A19: Number of turns | H19: #9 Hinge | I19: ='[1]Hardware Box'!$E19 -> 0 | J19: 4.12 | K19: =I19*J19 -> 0 | L19: 1.82 | M19: =I19*L19 -> 0
A20: # of Bearing Plates | H20: #10 Hinge | I20: ='[1]Hardware Box'!$E20 -> 0 | J20: 4.44 | K20: =I20*J20 -> 0 | L20: 8.11 | M20: =I20*L20 -> 0
I21: ='[1]Hardware Box'!$E21 -> 0 | J21: 4.93 | K21: =I21*J21 -> 0 | L21: 8.7 | M21: =I21*L21 -> 0
I22: ='[1]Hardware Box'!$E22 -> 0 | J22: 4.68 | K22: =I22*J22 -> 0 | L22: 8.75 | M22: =I22*L22 -> 0
I23: ='[1]Hardware Box'!$E23 -> 0 | K23: =I23*J23 -> 0 | M23: =I23*L23 -> 0
A24: Strut Clip (Pcs) | H24: 3'' Top Bracket | I24: ='[1]Hardware Box'!$E24 -> 2 | J24: 3.05 | K24: =I24*J24 -> 6.1 | L24: 1.73 | M24: =I24*L24 -> 3.46
A25: Strut Clip (Pcs) | H25: EZ123 Bottom Bracket | I25: ='[1]Hardware Box'!$E25 -> 2 | J25: 18.6 | K25: =I25*J25 -> 37.2 | L25: 10.74 | M25: =I25*L25 -> 21.48
A26: Z Strut (Length) | I26: ='[1]Hardware Box'!$E26 -> 0 | K26: =I26*J26 -> 0 | M26: =I26*L26 -> 0
A27: Connector (Pcs) | I27: ='[1]Hardware Box'!$E27 -> 0 | K27: =I27*J27 -> 0 | M27: =I27*L27 -> 0
A28: Z Straps Bended(Pcs) | H28: 3" L/S | I28: ='[1]Hardware Box'!$E28 -> 0 | J28: 3.47 | K28: =I28*J28 -> 0 | L28: 2.04 | M28: =I28*L28 -> 0
A29: Z Straps Straight(Pcs) | H29: 3'' S/S | I29: ='[1]Hardware Box'!$E29 -> 8 | J29: 3.66 | K29: =I29*J29 -> 29.28 | L29: 1.82 | M29: =I29*L29 -> 14.56
H30: 3" L/S for SEC | I30: ='[1]Hardware Box'!$E30 -> 4 | J30: 3.47 | K30: =I30*J30 -> 13.88 | L30: 2.04 | M30: =I30*L30 -> 8.16
A31: Cable Diam. & Length | B31: 0.15625 | C31: x 2 Pcs x | H31: Step Kit | I31: ='[1]Hardware Box'!$E31 -> 1 | J31: 0.44 | K31: =I31*J31 -> 0.44 | L31: 0.44 | M31: =I31*L31 -> 0.44
A32: Cable length exact (in) | C32: 144 | H32: Tek Screws | I32: ='[1]Hardware Box'!$E32 -> 88 | J32: 0.1 | K32: =I32*J32 -> 8.8 | L32: 0.1 | M32: =I32*L32 -> 8.8
A33: Door Weight | H33: Pull Rope #10 | I33: ='[1]Hardware Box'!$E33 -> 5 | J33: 0.25 | K33: =I33*J33 -> 1.25 | L33: 0.25 | M33: =I33*L33 -> 1.25
A34: Steel | B34: 238 | H34: Jamb Brackets & Spring Plates | I34: ='[1]Hardware Box'!$E34 -> 0
A35: Aluminum | B35: 0 | H35: #5 Angle Bracket | I35: ='[1]Hardware Box'!$E35 -> 2 | J35: 1.76 | K35: =I35*J35 -> 3.52 | L35: 0.46 | M35: =I35*L35 -> 0.92
A36: Glazing | B36: 0 | H36: #6 Angle Bracket | I36: ='[1]Hardware Box'!$E36 -> 2 | J36: =360/200 -> 1.8 | K36: =I36*J36 -> 3.6 | L36: 0.49 | M36: =I36*L36 -> 0.98
A37: Hardware | B37: 22 | H37: #7 Angle Bracket | I37: ='[1]Hardware Box'!$E37 -> 2 | J37: =365.71/200 -> 1.82855 | K37: =I37*J37 -> 3.6571 | L37: 0.51 | M37: =I37*L37 -> 1.02
A38: 20ga Struts | B38: 0 | H38: #8 Angle Bracket | I38: ='[1]Hardware Box'!$E38 -> 2 | J38: 1.88 | K38: =I38*J38 -> 3.76 | L38: 0.53 | M38: =I38*L38 -> 1.06
A39: 16ga Struts | B39: 0 | I39: ='[1]Hardware Box'!$E39 -> 0 | J39: 1.93 | K39: =I39*J39 -> 0 | L39: 0.55 | M39: =I39*L39 -> 0
A40: 34"x16" Thermo Windows | B40: 0 | I40: ='[1]Hardware Box'!$E40 -> 0 | J40: 1.99 | K40: =I40*J40 -> 0 | L40: 0.57 | M40: =I40*L40 -> 0
A41: 24"x12" Thermo Windows | B41: 0 | I41: ='[1]Hardware Box'!$E41 -> 0 | J41: 3.13 | K41: =I41*J41 -> 0 | L41: 0.6 | M41: =I41*L41 -> 0
...

Sheet High Lift
A1: High Lift Diagram
A2: Customer | D2: Work Order | E2: Door
A3: ='[1]Hardware Box'!A3 -> Sample | D3: ='[1]Hardware Box'!D3 -> 9999 | E3: ='[1]Hardware Box'!E3 -> 1/1
A5: Hilift | B5: ='Input Data'!$D$8 -> 45
A6: Door Height | B6: ='Input Data'!$D$5 -> 10 | C6: ='Input Data'!$E$5 -> 0 | E6: High Lift Jamb Brackets
A7: High Lift Bottom Offset | B7: ='Track B.O.M.'!$E$67 -> 2.625 | E7: # of Brackets | F7: =IF(ROUNDDOWN(1+B9/24,0)>2,ROUNDDOWN(1+B9/24,0),2) -> 7
A8: High Lift Top Offset | B8: ='Track B.O.M.'!$F$72 -> 8.7916667
A9: Track Length | B9: ='Track B.O.M.'!$E$70 -> 148 | E9: High Lift Bracket #'s | F9: Splice Plate
A10: Track Size | B10: ='[1]Hardware Box'!F7 -> 3
A11: Slotted Angle Length | B11: Distance from first High Lift Bracket to Last +15" | F11: =ROUNDDOWN(2.5+B7,0) -> 5
F12: =F11+1 -> 6
A13: Horizontal Angle Offset from Standard: | F13: =IF(F$7>2, F12+1,"") -> 7
A14: =B8-B7 -> 6.1666667 | F14: =IF(F$7>3, F13+1,"") -> 8

Sheet Spring Ass.Length
D2: Standard Lift
B3: Outer Spring | C3: Inner Spring | D3: Drum Size | E3: Max Door Height | F3: Width | G3: Max Weight per Drum | H3: Offset
A4: Coil | B4: 6 | C4: 3.75 | D4: D400-96 | E4: 96 | F4: 1.64 | G4: 265 | H4: 3-3/8" | L4: 6 | M4: 3.75
A5: Wire | B5: 0.343 | C5: 0.25 | D5: D400-144 | E5: 144 | F5: 2.63 | G5: 375 | H5: 3-3/8" | L5: 0.319 | M5: 0.25
A6: Spring Length | B6: 77 | C6: 34.5 | D6: D525-216 | E6: 216 | F6: 3.62 | G6: 750 | H6: 4-3/8" | L6: 37.5 | M6: 38.5
A7: Turns | B7: 14 | D7: D800-384 | E7: 384 | F7: 5.26 | G7: 1100 | H7: 5" * | L7: 14.7
A8: # of Springs | B8: 2 | L8: 2
A9: Space Between Springs | B9: 6
A10: Drum Width (Each) | B10: 4.29 | D10: High Lift
A11: Door width (W) | B11: 192 | D11: Drum Size | E11: Max High-Lift | F11: Width | G11: Max Weight per Drum | H11: Cable Capacity of Flat | I11: Max Door Height | J11: Offset
D12: D400-54 | E12: 54 | F12: 3.03 | G12: 275 | H12: 121 | I12: 174 | J12: 4-3/8"
A13: Assembly Length | B13: =(B5*B7+3+B6)*B8+(B8-1)*B9+B10*(2+'Input Data'!E18) -> 184.184 | D13: D525-54 | E13: 54 | F13: 3.66 | G13: 500 | H13: 179 | I13: 234 | J13: 4-3/8"
A14: Included the additional drum(s) width in spring assembly length calculation | D14: D575-120 | E14: 118 | F14: 3.71 | G14: 500 | H14: 145 | I14: 260 | J14: 5"
A15: Length available (W-6") | B15: =B11-6 -> 186 | C15: =IF(B13<B15,"Ok","Try again") -> Ok | D15: D6375-164 | E15: 164 | F15: 6.09 | G15: 800 | H15: 229 | I15: 393 | J15: 6" *
A16: Espace free per spring | B16: =(B11-B13)/B8 -> 3.908 | C16: =IF(B16<3,"Less than 3''","") | D16: D800-120 | E16: 119 | F16: 5.22 | G16: 1100 | H16: 266 | I16: 384 | J16: 6" *
H17: Hi-Lift = | I17: ='Input Data'!D8 -> 45
A18: Extended spring - 2 Rounds = | B18: =B6+B5*B7-2*B5 -> 81.116 | H18: Door Height = | I18: ='Input Data'!F5 -> 120
A19: Stationary + Winding Cones= | B19: 3 | H19: Cable Capacity of Flat | I19: =SUMIFS(H12:H16,D12:D16,'Input Data'!D9) -> 0
A20: Total extended spring length = | B20: =B18+B19 -> 84.116 | C20: each | H20: Door Height - High Lift < Capacity of Flat Portion = ? | I20: =IF((I18-I17)<I19,"Yes (Ok)","No") -> No
A22: =CONCATENATE("Total ",B8," Spring",IF(B8=1,"","(s)")," Weight") -> Total 2 Spring(s) Weight | B22: =H64 -> 282.7 | C22: Lbs | D22: Vertical Lift
B23: =B22/B8 -> 141.35 | D23: Drum Size | E23: Max Door Height | F23: Width | G23: Max Weight per Drum | H23: Offset
D24: D850-132 | E24: 132 | F24: 3.33 | G24: 425 | H24: 5"
A25: Spring full length | B25: 144 | D25: D1100-216 | E25: 216 | F25: 4.29 | G25: 660 | H25: 6"
A26: Spring cut length | B26: =B6 -> 77 | D26: D1350-336 | E26: 336 | F26: 6.75 | G26: 1100 | H26: 7" *
A27: Qty cuts per full length | B27: =ROUNDDOWN(B25/B26,0) -> 1 | D27: * Tracks Require Angle offset for large Drums
A28: Spring Length remaining | B28: =B25-B27*B26 -> 67
A29: Total springs required | B29: 8 | D29: Coil | E29: Wire | F29: Lbs/in | G29: 1 Spring Weight | H29: Total Spring Weight
A30: Total full length required | B30: =ROUNDUP(B29/B27,0) -> 8 | D30: 2 | E30: 0.218 | F30: 0.3389 | G30: =IF(AND(D30=$B$4,E30=$B$5),ROUND(F30*$B$6,2),IF(AND(D30=$C$4,E30=$C$5),ROUND(F30*$C$6,2),"")) | H30: =IF(G30="","",G30*$B$8)
D31: 2 | E31: 0.225 | F31: 0.3501 | G31: =IF(AND(D31=$B$4,E31=$B$5),ROUND(F31*$B$6,2),IF(AND(D31=$C$4,E31=$C$5),ROUND(F31*$C$6,2),"")) | H31: =IF(G31="","",G31*$B$8)
D32: 2 | E32: 0.234 | F32: 0.3657 | G32: =IF(AND(D32=$B$4,E32=$B$5),ROUND(F32*$B$6,2),IF(AND(D32=$C$4,E32=$C$5),ROUND(F32*$C$6,2),"")) | H32: =IF(G32="","",G32*$B$8)
A33: 1 spring length | B33: =B5*B7+B6+3 -> 84.802 | D33: 2 | E33: 0.243 | F33: 0.3818 | G33: =IF(AND(D33=$B$4,E33=$B$5),ROUND(F33*$B$6,2),IF(AND(D33=$C$4,E33=$C$5),ROUND(F33*$C$6,2),"")) | H33: =IF(G33="","",G33*$B$8)
D34: 2 | E34: 0.25 | F34: 0.3928 | G34: =IF(AND(D34=$B$4,E34=$B$5),ROUND(F34*$B$6,2),IF(AND(D34=$C$4,E34=$C$5),ROUND(F34*$C$6,2),"")) | H34: =IF(G34="","",G34*$B$8)
B35: =144/48.5 -> 2.9690722 | D35: 2 | E35: 0.262 | F35: 0.4147 | G35: =IF(AND(D35=$B$4,E35=$B$5),ROUND(F35*$B$6,2),IF(AND(D35=$C$4,E35=$C$5),ROUND(F35*$C$6,2),"")) | H35: =IF(G35="","",G35*$B$8)
B36: =144-2*48.5 -> 47 | D36: 2 | E36: 0.273 | F36: 0.4333 | G36: =IF(AND(D36=$B$4,E36=$B$5),ROUND(F36*$B$6,2),IF(AND(D36=$C$4,E36=$C$5),ROUND(F36*$C$6,2),"")) | H36: =IF(G36="","",G36*$B$8)
D37: 2 | E37: 0.283 | F37: 0.4512 | G37: =IF(AND(D37=$B$4,E37=$B$5),ROUND(F37*$B$6,2),IF(AND(D37=$C$4,E37=$C$5),ROUND(F37*$C$6,2),"")) | H37: =IF(G37="","",G37*$B$8)
D38: 2.625 | E38: 0.25 | F38: 0.5019 | G38: =IF(AND(D38=$B$4,E38=$B$5),ROUND(F38*$B$6,2),IF(AND(D38=$C$4,E38=$C$5),ROUND(F38*$C$6,2),"")) | H38: =IF(G38="","",G38*$B$8)
D39: 2.625 | E39: 0.262 | F39: 0.5293 | G39: =IF(AND(D39=$B$4,E39=$B$5),ROUND(F39*$B$6,2),IF(AND(D39=$C$4,E39=$C$5),ROUND(F39*$C$6,2),"")) | H39: =IF(G39="","",G39*$B$8)
D40: 2.625 | E40: 0.273 | F40: 0.5525 | G40: =IF(AND(D40=$B$4,E40=$B$5),ROUND(F40*$B$6,2),IF(AND(D40=$C$4,E40=$C$5),ROUND(F40*$C$6,2),"")) | H40: =IF(G40="","",G40*$B$8)
D41: 2.625 | E41: 0.283 | F41: 0.5747 | G41: =IF(AND(D41=$B$4,E41=$B$5),ROUND(F41*$B$6,2),IF(AND(D41=$C$4,E41=$C$5),ROUND(F41*$C$6,2),"")) | H41: =IF(G41="","",G41*$B$8)
D42: 2.625 | E42: 0.295 | F42: 0.6015 | G42: =IF(AND(D42=$B$4,E42=$B$5),ROUND(F42*$B$6,2),IF(AND(D42=$C$4,E42=$C$5),ROUND(F42*$C$6,2),"")) | H42: =IF(G42="","",G42*$B$8)
...

Sheet Sub Routine Drums
Q2: =660*2 -> 1320
B4: Track Size | C4: Drum Model | D4: Max Door Height (in) | E4: Drum Width (in) | F4: Drum Diam (in) | G4: Max Weight per Drum (lbs) | H4: Offset (in) | I4: Cable Diameter (in) 1 size below max | J4: Cable Diameter (in) | K4: Max High-Lift (in) | L4: Cable Capacity of Flat (in) | N4: Lift Type | O4: Track Size | P4: Max Door Height | Q4: Max Weight per Drum | R4: Max High-Lift | S4: Cable Capacity of Flat | T4: Drum Model | V4: Cable Diam Selected | X4: HMA | Y4: LMA | Z4: Radius | AA4: Std Lift Open Weight | AB4: LHR Open Weight | AC4: Pitch Track Open Weight
A5: Vertical Lift | C5: D850-132 | D5: 132 | E5: 3.33 | F5: 8.63 | G5: 425 | H5: 5" | I5: 0.15625 | J5: 0.1875 | N5: =IF(A5='Input Data'!$D$7,1,0) -> 1 | O5: 1 | P5: =IF(D5>='Input Data'!$F$5,1,0) -> 1 | Q5: =IF(G5*(2+'Input Data'!$E$18)>='Input Data'!K$40,1,0) -> 1 | T5: =N5*P5*Q5 -> 1 | U5: 10 | V5: =IF($S$17=C5,IF('Input Data'!$K$40<=(1+'Input Data'!$E$18/2)*SUMIFS('Sub Routine Drums'!$J$25:$J$28,'Sub Routine Drums'!$I$25:$I$28,I5),I5,IF('Input Data'!$K$40<=(1+'Input Data'!$E$18/2)*SUMIFS('Sub Routine Drums'!$J$25:$J$28,'Sub Routine Drums'!$I$25:$I$28,J5),J5,"DW > Cable Capacity")),"") -> 0.15625 | Y5: 1.344
A6: Vertical Lift | C6: D1100-216 | D6: 216 | E6: 4.29 | F6: 10.88 | G6: 660 | H6: 6" | I6: 0.15625 | J6: 0.1875 | N6: =IF(A6='Input Data'!$D$7,1,0) -> 1 | O6: 1 | P6: =IF(D6>='Input Data'!$F$5,1,0) -> 1 | Q6: =IF(G6*(2+'Input Data'!$E$18)>='Input Data'!K$40,1,0) -> 1 | T6: =N6*P6*Q6 -> 1 | U6: 11 | V6: =IF($S$17=C6,IF('Input Data'!$K$40<=(1+'Input Data'!$E$18/2)*SUMIFS('Sub Routine Drums'!$J$25:$J$28,'Sub Routine Drums'!$I$25:$I$28,I6),I6,IF('Input Data'!$K$40<=(1+'Input Data'!$E$18/2)*SUMIFS('Sub Routine Drums'!$J$25:$J$28,'Sub Routine Drums'!$I$25:$I$28,J6),J6,"DW > Cable Capacity")),"") | Y6: 1.344
A7: Vertical Lift | C7: D1350-336 | D7: 336 | E7: 6.75 | F7: 13.45 | G7: 1100 | H7: 7" | I7: 0.1875 | J7: 0.25 | N7: =IF(A7='Input Data'!$D$7,1,0) -> 1 | O7: 1 | P7: =IF(D7>='Input Data'!$F$5,1,0) -> 1 | Q7: =IF(G7*(2+'Input Data'!$E$18)>='Input Data'!K$40,1,0) -> 1 | T7: =N7*P7*Q7 -> 1 | U7: 12 | V7: =IF($S$17=C7,IF('Input Data'!$K$40<=(1+'Input Data'!$E$18/2)*SUMIFS('Sub Routine Drums'!$J$25:$J$28,'Sub Routine Drums'!$I$25:$I$28,I7),I7,IF('Input Data'!$K$40<=(1+'Input Data'!$E$18/2)*SUMIFS('Sub Routine Drums'!$J$25:$J$28,'Sub Routine Drums'!$I$25:$I$28,J7),J7,"DW > Cable Capacity")),"") | Y7: 1.375
